<mujoco model='ADROIT-door(v1.5)'>

    <!-- ======= WORLD ======= -->
    <worldbody>
        <light directional='false' diffuse='.7 .7 .7' specular='0.03 0.03 0.03' pos='-1 -1.0 4.0' dir='1 1.0 -4'/>
        <!-- <geom name='ground' size="1.5 1.5 0.25" pos="0 0 -1" type="plane" contype="1" conaffinity="0" material="groundplane" /> -->
        <camera name="fixed" pos="0 -0.7 0.7" quat="0.92388 0.382683 0 0" />
        <!-- Camera for the VIL paper -->
        <!-- <camera name="vil_camera" pos="0 -1.2 1.2" quat="0.92388 0.382683 0 0" />
        <camera name="view_1" pos="-0.8 -0.8 0.8" euler="0.785 -0.785 -0.785" />
        <camera name="view_2" pos="0 0.5 0.2" euler="-1.57 0 3.14" />
        <camera name="view_3" pos="0 0.2 -0.2" euler="-2.35 0 3.14" />
        <camera name="view_4" pos="0.8 -0.8 0.8" euler="0.785 0.785 0.785" />
        <camera name="view_5" pos="0 -0.25 -0.4" euler="-3.2 0 3.14" />
        <camera name="top" pos="0 0 1.5" euler="0 0 3.14" /> -->

        <!-- ======= DOOR ======= -->
        <body name="frame" pos="-0.128807 0.0522352 0.5368512" user="1001 0 2002 -0.48 -0.12 0.3024 0 0.36 0.54">
            <inertial pos="0.348 0 0" quat="0.5 0.5 0.5 0.5" mass="7.85398" diaginertia="1.1079612 0.917502 0.2022396" />
            <geom size="0.06 0.3" pos="0.72 0 0" type="cylinder" material="MatWood" rgba="1 0 0 1" />
            <geom size="0.06 0.3" pos="-0.024 0 0" type="cylinder" material="MatWood" rgba="1 0 0 1" />
            <site name="S_handle_target" pos="0.9 -0.6 -0.216" size="0.03" group='3'/>
            <body name="door" pos="0.348 0 0">
                <inertial pos="0.03561792 -0.00182814 0" quat="0.701072 0 0 0.713091" mass="2.43455" diaginertia="0.10965012 0.0625938 0.0524568" />
                <joint name="door_hinge" pos="0.372 0 0" axis="0 0 1" range="0 1.57" damping="1" frictionloss="2" />
                <geom size="0.24 0.06 0.3" type="box" friction="1 1 1" material="MatWood" />
                <geom size="0.06 0.3" pos="0.24 0 0" type="cylinder" material="MatWood" />
                <geom size="0.06 0.3" pos="-0.24 0 0" type="cylinder" material="MatWood" />
                <body name="latch" pos="-0.18 0 -0.03">
                    <inertial pos="-0.0213144 0.01662528 0" quat="0.365653 0.605347 -0.36522 0.605365" mass="3.53743" diaginertia="0.05805252 0.04932012 0.01332156" />
                    <joint name="latch" pos="0 0 0" axis="0 1 0" range="0 1.8" frictionloss="5" />
                    <geom size="0.06 0.18" quat="0.707388 0.706825 0 0" type="cylinder" material="MatFoil" />
                    <geom size="0.024 0.12" pos="0.12 -0.18 0" quat="0.707388 0 0.706825 0" type="capsule" material="MatFoil" />
                    <geom size="0.048 0.084" pos="-0.12 0.12 0" quat="0.707388 0 0.706825 0" type="capsule" material="MatFoil" />
                    <site name="S_handle" pos="0.18 -0.18 0" size="0.03" group='3'/>
                </body>
            </body>
        </body>
        <!-- <geom type="mesh" mesh="robohive" conaffinity="0" contype="0" rgba=".5 .5 .5 1" pos="0 0.075 -1"/> -->

    </worldbody>

    <include file='assets.xml'/>

</mujoco>